Workbook

Sheet 로켓그로스 입고
D1: *지난 1개월 매출순 기준으로 로켓그로스 판매 가능한 상품 목록입니다. 로켓그로스에서 운영하지 않는 카테고리나 품목은 제외되었습니다. *로켓그로스 입고 필수 정보를 입력하고 윙 [로켓그로스 > 입고관리 > 입고요청 > 상품선택 > 엑셀 업로드]에서 엑셀 파일을 업로드하고 배송을 생성해주세요. | V1: *로켓그로스 입고 필수정보 로켓그로스로 입고하려면 파란색 테두리의 정보를 입력 후 엑셀파일을 윙에서 업로드해주세요 | AC1: *엑셀 업로드 바로가기 ▶ | AE1: 1. 좌측 하단의 파란색 테두리를 입력한 후 좌측 바로가기를 눌러 본 엑셀 파일을 윙에 업로드해주세요. 2. 업로드 완료 후 윙의 안내에 따라 입고절차를 진행해주세요.
B2: 상품명 | D2: 판매가 | E2: 상품정보 | I2: 최근 상품별 매출정보(원) | Q2: 로켓그로스 수수료/서비스 예상 요금 | V2: 입고 수량 | X2: 유통기간 | AB2: 물류 정보 | AE2: 상품추가정보
A3: No. | B3: 등록상품명 | C3: 옵션명 | D3: 판매가 | E3: 노출상품 ID | F3: 등록상품 ID | G3: 옵션 ID | H3: 판매 방식 | I3: 22년 총계 | J3: 23년 총계 | K3: 23년 3월 | L3: 23년 2월 | M3: 23년 1월 | N3: 지난 14일 | O3: 2주간 판매수량 | P3: 1주간 판매수량 | Q3: 판매자 수수료율 | R3: 판매자 수수료 | S3: 쿠팡풀필먼트서비스 예상 요금(개당) (입출고요금+배송료 / 보관료 미포함) | T3: 기본 할인액 | U3: 할인 적용 예상 요금 | V3: 입고 수량 입력 (필수) | W3: 입고수량에 따른 2주간 예상 매출 | X3: 유통기간 입력 (해당 시 필수) | Y3: 유통(소비)기한 (필수) | Z3: 제조일자 (필수) | AA3: 생산년도 (필수) | AB3: 상품바코드 (필수) | AC3: 상품 사이즈 (필수) | AD3: 취급주의여부 (필수) | AE3: 판매가능재고 | AF3: 예상 재고 소진일 | AG3: 카테고리 | AH3: 병행수입 여부 | AI3: 과세유형 | AJ3: SKU ID | AK3: Req exp date | AL3: Req man date | AM3: Req prod year
A4: 예시 및 설명 | B4: 스누피 티셔츠 | C4: 블랙 S | D4: 25000 | E4: 7269865933 | F4: 14047501199 | G4: 85676422188 | H4: 판매자배송 | I4: 동일상품 기준 합산 매출 (로켓그로스 포함) | J4: 동일상품 기준 합산 매출 (로켓그로스 포함) | K4: 동일상품 기준 합산 매출 (로켓그로스 포함) | L4: 동일상품 기준 합산 매출 (로켓그로스 포함) | M4: 동일상품 기준 합산 매출 (로켓그로스 포함) | N4: 동일상품 기준 합산 매출 (로켓그로스 포함) | O4: 이전 14일 기준 (단위: 개) | P4: 이전 7일 기준 (단위: 개) | R4: (댠위: 원) | S4: 입고수량을 입력하고 예상 수수료를 알아보세요 물류센터의 상품 실측 이후 요금은 달라질 수 있습니다. | V4: 판매기간 2주 기준 추천된 수량이며, 판매자가 변경할 수 있습니다. | W4: 입고수량 X 판매가 | X4: 일 단위로 입력 | Y4: 상품별 기한이 다를 경우, 가장 빠른 날짜로 입력해 주세요. | Z4: 상품별 기한이 다를 경우, 가장 빠른 날짜로 입력해 주세요. | AA4: 상품별 기한이 다를 경우, 가장 빠른 날짜로 입력해 주세요. | AB4: 미입력시 쿠팡 바코드가 자동 생성되며, 상품마다 바코드를 출력해서 부착해야 합니다. | AC4: 상품 사이즈 분류 기준이 궁금하세요? 바로가기 | AD4: 취급주의 상품(유리 제품, 칼, 페인트)에 해당할 시 표기해주세요.
A5: 130 | B5: 수_A76_로웰 | C5: 베이지 245 | D5: 19800 | E5: 6874685732 | F5: 13652398681 | G5: 83647786494 | H5: 로켓그로스 | V5: =VLOOKUP(AB5,바코드찍는곳!B:C,2,0) -> 2 | Y5: 선택입력 | Z5: 선택입력 | AA5: 선택입력 | AB5: S0024914486721 | AC5: Small | AD5: 해당아님 | AE5: 0 | AG5: 여성일반/사무용슬리퍼 | AH5: 비병행수입 | AI5: 과세
A6: 177 | B6: 수_6063_위트니 | C6: 브라운 255 | D6: 26800 | E6: 6870123487 | F6: 13648056106 | G6: 83622793076 | H6: 로켓그로스 | V6: =VLOOKUP(AB6,바코드찍는곳!B:C,2,0) -> 1 | Y6: 선택입력 | Z6: 선택입력 | AA6: 선택입력 | AB6: S0024887568839 | AC6: Small | AD6: 해당아님 | AE6: 0 | AG6: 여성스트랩샌들 | AH6: 비병행수입 | AI6: 과세
A7: 403 | B7: 수_7-22_블랑카뮬 | C7: 실버 235 | D7: 28400 | E7: 6855868928 | F7: 13630882807 | G7: 83541490561 | H7: 로켓그로스 | V7: =VLOOKUP(AB7,바코드찍는곳!B:C,2,0) -> 1 | Y7: 선택입력 | Z7: 선택입력 | AA7: 선택입력 | AB7: S0024782192317 | AC7: Small | AD7: 해당아님 | AE7: 0 | AG7: 여성뮬/슬리퍼형샌들 | AH7: 비병행수입 | AI7: 과세
A8: 404 | B8: 수_7-22_블랑카뮬 | C8: 실버 240 | D8: 28400 | E8: 6855868928 | F8: 13630882807 | G8: 83541490578 | H8: 로켓그로스 | V8: =VLOOKUP(AB8,바코드찍는곳!B:C,2,0) -> 1 | Y8: 선택입력 | Z8: 선택입력 | AA8: 선택입력 | AB8: S0024782192318 | AC8: Small | AD8: 해당아님 | AE8: 0 | AG8: 여성뮬/슬리퍼형샌들 | AH8: 비병행수입 | AI8: 과세
A9: 450 | B9: 수_7050_포코린7cm | C9: 블랙 230 | D9: 29800 | E9: 6850354239 | F9: 13625868722 | G9: 83509624457 | H9: 로켓그로스 | V9: =VLOOKUP(AB9,바코드찍는곳!B:C,2,0) -> 1 | Y9: 선택입력 | Z9: 선택입력 | AA9: 선택입력 | AB9: S0024749832788 | AC9: Small | AD9: 해당아님 | AE9: 0 | AG9: 여성스트랩샌들 | AH9: 비병행수입 | AI9: 과세
A10: 460 | B10: 수_7050_포코린7cm | C10: 베이지 250 | D10: 29800 | E10: 6850354239 | F10: 13625868722 | G10: 83509624612 | H10: 로켓그로스 | V10: =VLOOKUP(AB10,바코드찍는곳!B:C,2,0) -> 1 | Y10: 선택입력 | Z10: 선택입력 | AA10: 선택입력 | AB10: S0024749832812 | AC10: Small | AD10: 해당아님 | AE10: 0 | AG10: 여성스트랩샌들 | AH10: 비병행수입 | AI10: 과세
A11: 480 | B11: 수_5035_포코린5cm | C11: 베이지 230 | D11: 29800 | E11: 6850351782 | F11: 13625307987 | G11: 83509608132 | H11: 로켓그로스 | V11: =VLOOKUP(AB11,바코드찍는곳!B:C,2,0) -> 1 | Y11: 선택입력 | Z11: 선택입력 | AA11: 선택입력 | AB11: S0024746975982 | AC11: Small | AD11: 해당아님 | AE11: 0 | AG11: 여성스트랩샌들 | AH11: 비병행수입 | AI11: 과세
A12: 481 | B12: 수_5035_포코린5cm | C12: 베이지 235 | D12: 29800 | E12: 6850351782 | F12: 13625307987 | G12: 83509608145 | H12: 로켓그로스 | V12: =VLOOKUP(AB12,바코드찍는곳!B:C,2,0) -> 1 | Y12: 선택입력 | Z12: 선택입력 | AA12: 선택입력 | AB12: S0024746975983 | AC12: Small | AD12: 해당아님 | AE12: 0 | AG12: 여성스트랩샌들 | AH12: 비병행수입 | AI12: 과세
A13: 525 | B13: 수_7068_트루디 | C13: 블랙 245 | D13: 27800 | E13: 6842303418 | F13: 13619931021 | G13: 83466882382 | H13: 로켓그로스 | V13: =VLOOKUP(AB13,바코드찍는곳!B:C,2,0) -> 2 | Y13: 선택입력 | Z13: 선택입력 | AA13: 선택입력 | AB13: S0024717098378 | AC13: Small | AD13: 해당아님 | AE13: 0 | AG13: 여성일반/사무용슬리퍼 | AH13: 비병행수입 | AI13: 과세
A14: 540 | B14: 발편한 베이직 스판 슬림핏 앵클 여성 부츠 | C14: 화이트 235 | D14: 36100 | E14: 6840732990 | F14: 13618338242 | G14: 83458632581 | H14: 로켓그로스 | V14: =VLOOKUP(AB14,바코드찍는곳!B:C,2,0) -> 2 | Y14: 선택입력 | Z14: 선택입력 | AA14: 선택입력 | AB14: S0024708192150 | AC14: Small | AD14: 해당아님 | AE14: 0 | AG14: 여성앵클부츠 | AH14: 비병행수입 | AI14: 과세
A15: 541 | B15: 발편한 베이직 스판 슬림핏 앵클 여성 부츠 | C15: 화이트 240 | D15: 36100 | E15: 6840732990 | F15: 13618338242 | G15: 83458632592 | H15: 로켓그로스 | V15: =VLOOKUP(AB15,바코드찍는곳!B:C,2,0) -> 2 | Y15: 선택입력 | Z15: 선택입력 | AA15: 선택입력 | AB15: S0024708192151 | AC15: Small | AD15: 해당아님 | AE15: 0 | AG15: 여성앵클부츠 | AH15: 비병행수입 | AI15: 과세
A16: 542 | B16: 발편한 베이직 스판 슬림핏 앵클 여성 부츠 | C16: 화이트 245 | D16: 36100 | E16: 6840732990 | F16: 13618338242 | G16: 83458632600 | H16: 로켓그로스 | V16: =VLOOKUP(AB16,바코드찍는곳!B:C,2,0) -> 1 | Y16: 선택입력 | Z16: 선택입력 | AA16: 선택입력 | AB16: S0024708192152 | AC16: Small | AD16: 해당아님 | AE16: 0 | AG16: 여성앵클부츠 | AH16: 비병행수입 | AI16: 과세
... A33: 1066 | B33: 수_7012_제인 | C33: 베이지 230 | D33: 30800 | E33: 6795174369 | F33: 13574507277 | G33: 83225492397 | H33: 로켓그로스 | V33: =VLOOKUP(AB33,바코드찍는곳!B:C,2,0) -> 2 | Y33: 선택입력 | Z33: 선택입력 | AA33: 선택입력 | AB33: S0024451269450 | AC33: Small | AD33: 해당아님 | AE33: 0 | AG33: 여성일반하이힐 | AH33: 비병행수입 | AI33: 과세
A34: 1165 | B34: 수_5058_아만다 | C34: 블랙 260 | D34: 32800 | E34: 7551469719 | F34: 13570400899 | G34: 83207385293 | H34: 로켓그로스 | V34: =VLOOKUP(AB34,바코드찍는곳!B:C,2,0) -> 1 | Y34: 선택입력 | Z34: 선택입력 | AA34: 선택입력 | AB34: S0024426390882 | AC34: Small | AD34: 해당아님 | AE34: 0 | AG34: 여성슬링백 | AH34: 비병행수입 | AI34: 과세
A35: 1184 | B35: 수_5058_아만다 | C35: 아이보리 265 | D35: 32800 | E35: 7551469719 | F35: 13570400899 | G35: 83207385474 | H35: 로켓그로스 | V35: =VLOOKUP(AB35,바코드찍는곳!B:C,2,0) -> 1 | Y35: 선택입력 | Z35: 선택입력 | AA35: 선택입력 | AB35: S0024426390901 | AC35: Small | AD35: 해당아님 | AE35: 0 | AG35: 여성슬링백 | AH35: 비병행수입 | AI35: 과세
A36: 1201 | B36: 수_4015_리디카 | C36: 핑크베이지 260 | D36: 34400 | E36: 6790087572 | F36: 13569751133 | G36: 83200586730 | H36: 로켓그로스 | V36: =VLOOKUP(AB36,바코드찍는곳!B:C,2,0) -> 1 | Y36: 선택입력 | Z36: 선택입력 | AA36: 선택입력 | AB36: S0024423311592 | AC36: Small | AD36: 해당아님 | AE36: 0 | AG36: 여성일반하이힐 | AH36: 비병행수입 | AI36: 과세
A37: 1339 | B37: 수_w6019_에렌 | C37: 화이트 230 | D37: 24500 | E37: 6761436184 | F37: 13542453839 | G37: 83057523375 | H37: 로켓그로스 | V37: =VLOOKUP(AB37,바코드찍는곳!B:C,2,0) -> 2 | Y37: 선택입력 | Z37: 선택입력 | AA37: 선택입력 | AB37: S0024262981742 | AC37: Small | AD37: 해당아님 | AE37: 0 | AG37: 여성블로퍼 | AH37: 비병행수입 | AI37: 과세
A38: 1390 | B38: 수_6065_필리스 | C38: 다크 브라운 240 | D38: 27800 | E38: 6761251874 | F38: 13541702733 | G38: 83056820661 | H38: 로켓그로스 | V38: =VLOOKUP(AB38,바코드찍는곳!B:C,2,0) -> 2 | Y38: 선택입력 | Z38: 선택입력 | AA38: 선택입력 | AB38: S0024259535270 | AC38: Small | AD38: 해당아님 | AE38: 0 | AG38: 여성로퍼 | AH38: 비병행수입 | AI38: 과세
A39: 1393 | B39: 수_6065_필리스 | C39: 다크 브라운 255 | D39: 27800 | E39: 6761251874 | F39: 13541702733 | G39: 83056820678 | H39: 로켓그로스 | V39: =VLOOKUP(AB39,바코드찍는곳!B:C,2,0) -> 2 | Y39: 선택입력 | Z39: 선택입력 | AA39: 선택입력 | AB39: S0024259535274 | AC39: Small | AD39: 해당아님 | AE39: 0 | AG39: 여성로퍼 | AH39: 비병행수입 | AI39: 과세
A40: 1399 | B40: 수_6065_필리스 | C40: 카멜 245 | D40: 27800 | E40: 6761251874 | F40: 13541702733 | G40: 83056820731 | H40: 로켓그로스 | V40: =VLOOKUP(AB40,바코드찍는곳!B:C,2,0) -> 2 | Y40: 선택입력 | Z40: 선택입력 | AA40: 선택입력 | AB40: S0024259535280 | AC40: Small | AD40: 해당아님 | AE40: 0 | AG40: 여성로퍼 | AH40: 비병행수입 | AI40: 과세
A41: 1403 | B41: 수_6065_필리스 | C41: 카멜 265 | D41: 27800 | E41: 6761251874 | F41: 13541702733 | G41: 83056820783 | H41: 로켓그로스 | V41: =VLOOKUP(AB41,바코드찍는곳!B:C,2,0) -> 2 | Y41: 선택입력 | Z41: 선택입력 | AA41: 선택입력 | AB41: S0024259535285 | AC41: Small | AD41: 해당아님 | AE41: 0 | AG41: 여성로퍼 | AH41: 비병행수입 | AI41: 과세
A42: 1422 | B42: 수_6064_엘렌 | C42: 카멜 230 | D42: 24200 | E42: 6760740275 | F42: 13540136832 | G42: 83044976755 | H42: 로켓그로스 | V42: =VLOOKUP(AB42,바코드찍는곳!B:C,2,0) -> 2 | Y42: 선택입력 | Z42: 선택입력 | AA42: 선택입력 | AB42: S0024249277769 | AC42: Small | AD42: 해당아님 | AE42: 0 | AG42: 여성로퍼 | AH42: 비병행수입 | AI42: 과세
A43: 1453 | B43: 수_6061_라비나 | C43: 블랙 255 | D43: 31800 | E43: 6760681987 | F43: 13539926697 | G43: 83054582735 | H43: 로켓그로스 | V43: =VLOOKUP(AB43,바코드찍는곳!B:C,2,0) -> 2 | Y43: 선택입력 | Z43: 선택입력 | AA43: 선택입력 | AB43: S0024248299205 | AC43: Small | AD43: 해당아님 | AE43: 0 | AG43: 여성로퍼 | AH43: 비병행수입 | AI43: 과세
A44: 1522 | B44: 수_5064_소피아 | C44: 화이트 235 | D44: 28800 | E44: 6756534015 | F44: 13537833642 | G44: 83032311575 | H44: 로켓그로스 | V44: =VLOOKUP(AB44,바코드찍는곳!B:C,2,0) -> 1 | Y44: 선택입력 | Z44: 선택입력 | AA44: 선택입력 | AB44: S0024235399139 | AC44: Small | AD44: 해당아님 | AE44: 0 | AG44: 여성블로퍼 | AH44: 비병행수입 | AI44: 과세
A45: 1535 | B45: 수_30059_미라클 | C45: 블랙 255 | D45: 27400 | E45: 6756366769 | F45: 13537676176 | G45: 83031540848 | H45: 로켓그로스 | V45: =VLOOKUP(AB45,바코드찍는곳!B:C,2,0) -> 3 | Y45: 선택입력 | Z45: 선택입력 | AA45: 선택입력 | AB45: S0024234551762 | AC45: Small | AD45: 해당아님 | AE45: 0 | AG45: 여성블로퍼 | AH45: 비병행수입 | AI45: 과세
A46: 1537 | B46: 수_30059_미라클 | C46: 블랙 265 | D46: 27400 | E46: 6756366769 | F46: 13537676176 | G46: 83031540866 | H46: 로켓그로스 | V46: =VLOOKUP(AB46,바코드찍는곳!B:C,2,0) -> 2 | Y46: 선택입력 | Z46: 선택입력 | AA46: 선택입력 | AB46: S0024234551764 | AC46: Small | AD46: 해당아님 | AE46: 0 | AG46: 여성블로퍼 | AH46: 비병행수입 | AI46: 과세
A47: 1544 | B47: 수_30059_미라클 | C47: 베이지 255 | D47: 27400 | E47: 6756366769 | F47: 13537676176 | G47: 83031540923 | H47: 로켓그로스 | V47: =VLOOKUP(AB47,바코드찍는곳!B:C,2,0) -> 2 | Y47: 선택입력 | Z47: 선택입력 | AA47: 선택입력 | AB47: S0024234551777 | AC47: Small | AD47: 해당아님 | AE47: 0 | AG47: 여성블로퍼 | AH47: 비병행수입 | AI47: 과세
... A67: 2403 | B67: 수_5007 | C67: 화이트 265 | D67: 21800 | E67: 6547701658 | F67: 13316600960 | G67: 81789597266 | H67: 로켓그로스 | V67: =VLOOKUP(AB67,바코드찍는곳!B:C,2,0) -> 2 | Y67: 선택입력 | Z67: 선택입력 | AA67: 선택입력 | AB67: SOO8809798696813 | AC67: Small | AD67: 해당아님 | AE67: 0 | AG67: 여성뮬/슬리퍼형샌들 | AH67: 비병행수입 | AI67: 과세
A68: 2406 | B68: 수_5043 | C68: 블랙 235 | D68: 27800 | E68: 6537346068 | F68: 13315357631 | G68: 81783741942 | H68: 로켓그로스 | V68: =VLOOKUP(AB68,바코드찍는곳!B:C,2,0) -> 2 | Y68: 선택입력 | Z68: 선택입력 | AA68: 선택입력 | AB68: 8809816389055 | AC68: Small | AD68: 해당아님 | AE68: 0 | AG68: 여성뮬/슬리퍼형샌들 | AH68: 비병행수입 | AI68: 과세
A69: 2410 | B69: 수_5043 | C69: 블랙 255 | D69: 27800 | E69: 6537346068 | F69: 13315357631 | G69: 81783741990 | H69: 로켓그로스 | V69: =VLOOKUP(AB69,바코드찍는곳!B:C,2,0) -> 1 | Y69: 선택입력 | Z69: 선택입력 | AA69: 선택입력 | AB69: 8809816389093 | AC69: Small | AD69: 해당아님 | AE69: 0 | AG69: 여성뮬/슬리퍼형샌들 | AH69: 비병행수입 | AI69: 과세
A70: 2420 | B70: 수_5043 | C70: 베이지 260 | D70: 27800 | E70: 6537346068 | F70: 13315357631 | G70: 81783742079 | H70: 로켓그로스 | V70: =VLOOKUP(AB70,바코드찍는곳!B:C,2,0) -> 2 | Y70: 선택입력 | Z70: 선택입력 | AA70: 선택입력 | AB70: 8809816389192 | AC70: Small | AD70: 해당아님 | AE70: 0 | AG70: 여성뮬/슬리퍼형샌들 | AH70: 비병행수입 | AI70: 과세
A71: 2425 | B71: 수_5043 | C71: 화이트 240 | D71: 27800 | E71: 6537346068 | F71: 13315357631 | G71: 81783742134 | H71: 로켓그로스 | V71: =VLOOKUP(AB71,바코드찍는곳!B:C,2,0) -> 2 | Y71: 선택입력 | Z71: 선택입력 | AA71: 선택입력 | AB71: 8809816389246 | AC71: Small | AD71: 해당아님 | AE71: 0 | AG71: 여성뮬/슬리퍼형샌들 | AH71: 비병행수입 | AI71: 과세
A72: 2428 | B72: 수_5043 | C72: 화이트 255 | D72: 27800 | E72: 6537346068 | F72: 13315357631 | G72: 81783742171 | H72: 로켓그로스 | V72: =VLOOKUP(AB72,바코드찍는곳!B:C,2,0) -> 2 | Y72: 선택입력 | Z72: 선택입력 | AA72: 선택입력 | AB72: 8809816389277 | AC72: Small | AD72: 해당아님 | AE72: 0 | AG72: 여성뮬/슬리퍼형샌들 | AH72: 비병행수입 | AI72: 과세
A73: 2437 | B73: 수_5042TC | C73: 블랙 255 | D73: 32460 | E73: 6537040943 | F73: 13315106644 | G73: 81782214893 | H73: 로켓그로스 | V73: =VLOOKUP(AB73,바코드찍는곳!B:C,2,0) -> 1 | Y73: 선택입력 | Z73: 선택입력 | AA73: 선택입력 | AB73: 8809792688357 | AC73: Small | AD73: 해당아님 | AE73: 0 | AG73: 여성일반하이힐 | AH73: 비병행수입 | AI73: 과세
A74: 2441 | B74: 수_5042TC | C74: 베이지 230 | D74: 32460 | E74: 6537040943 | F74: 13315106644 | G74: 81782215064 | H74: 로켓그로스 | V74: =VLOOKUP(AB74,바코드찍는곳!B:C,2,0) -> 2 | Y74: 선택입력 | Z74: 선택입력 | AA74: 선택입력 | AB74: 8809792688395 | AC74: Small | AD74: 해당아님 | AE74: 0 | AG74: 여성일반하이힐 | AH74: 비병행수입 | AI74: 과세
A75: 2464 | B75: 수_N2-2_카라 | C75: 베이지 265 | D75: 29800 | E75: 7358199198 | F75: 14137103458 | G75: 86077917227 | H75: 로켓그로스 | V75: =VLOOKUP(AB75,바코드찍는곳!B:C,2,0) -> 1 | Y75: 선택입력 | Z75: 선택입력 | AA75: 선택입력 | AB75: 8809848769108 | AC75: Small | AD75: 해당아님 | AE75: 0 | AG75: 여성슬링백 | AH75: 비병행수입 | AI75: 과세
...

Sheet 바코드찍는곳
A1: 바코드 찍는곳 | B1: 바코드 중복제거 | C1: 입고 총 수량
A2: S0024161604506 | C2: =COUNTIF(A:A,B2) -> 0
A3: S0024522061275 | B3: S0024522061275 | C3: =COUNTIF(A:A,B3) -> 2
A4: S0024451269450 | B4: S0024451269450 | C4: =COUNTIF(A:A,B4) -> 2
A5: S0024234551762 | B5: S0024234551762 | C5: =COUNTIF(A:A,B5) -> 3
A6: S0024161604506 | B6: S0024161604506 | C6: =COUNTIF(A:A,B6) -> 2
A7: S0024454375941 | B7: S0024454375941 | C7: =COUNTIF(A:A,B7) -> 1
A8: S0024248299205 | B8: S0024248299205 | C8: =COUNTIF(A:A,B8) -> 2
A9: S0024695686449 | B9: S0024695686449 | C9: =COUNTIF(A:A,B9) -> 2
A10: S0024717098378 | B10: S0024717098378 | C10: =COUNTIF(A:A,B10) -> 2
A11: S0024093194652 | B11: S0024093194652 | C11: =COUNTIF(A:A,B11) -> 2
A12: S0031452694336 | B12: S0031452694336 | C12: =COUNTIF(A:A,B12) -> 2
A13: S0031452694336 | B13: S0024235399139 | C13: =COUNTIF(A:A,B13) -> 1
A14: S0024235399139 | B14: S0031452694351 | C14: =COUNTIF(A:A,B14) -> 1
... A18: S0024248299205 | B18: S0031952342924 | C18: =COUNTIF(A:A,B18) -> 2
A19: S0031952342921 | B19: 8809848769481 | C19: =COUNTIF(A:A,B19) -> 2
A20: S0031952342924 | B20: 8809848769610 | C20: =COUNTIF(A:A,B20) -> 2
A21: S0031952342924 | B21: S0024011472603 | C21: =COUNTIF(A:A,B21) -> 2
A22: 8809848769481 | B22: S0024550143934 | C22: =COUNTIF(A:A,B22) -> 2
A23: 8809848769481 | B23: S0024454375920 | C23: =COUNTIF(A:A,B23) -> 1
A24: 8809848769610 | B24: S0024454375912 | C24: =COUNTIF(A:A,B24) -> 1
A25: S0024011472603 | B25: S0024749832788 | C25: =COUNTIF(A:A,B25) -> 1
A26: S0024550143934 | B26: S0024624868641 | C26: =COUNTIF(A:A,B26) -> 2
A27: S0024454375920 | B27: S0024552955600 | C27: =COUNTIF(A:A,B27) -> 2
A28: S0024454375912 | B28: S0024708192152 | C28: =COUNTIF(A:A,B28) -> 1
A29: S0024749832788 | B29: 8800242294845 | C29: =COUNTIF(A:A,B29) -> 1
A30: S0024624868641 | B30: 8809848769641 | C30: =COUNTIF(A:A,B30) -> 2
A31: S0024234551762 | B31: 8800242294838 | C31: =COUNTIF(A:A,B31) -> 2
A32: S0024552955600 | B32: S0024262981742 | C32: =COUNTIF(A:A,B32) -> 2
A33: S0024552955600 | B33: S0024749832812 | C33: =COUNTIF(A:A,B33) -> 1
A34: S0024708192152 | B34: S0024782192318 | C34: =COUNTIF(A:A,B34) -> 1
A35: 8800242294845 | B35: S0024746975982 | C35: =COUNTIF(A:A,B35) -> 1
A36: 8809848769610 | B36: S0024426390882 | C36: =COUNTIF(A:A,B36) -> 1
A37: 8809848769641 | B37: S0024249277769 | C37: =COUNTIF(A:A,B37) -> 2
A38: 8800242294838 | B38: S0024234551764 | C38: =COUNTIF(A:A,B38) -> 2
A39: 8800242294838 | B39: S0024683376528 | C39: =COUNTIF(A:A,B39) -> 2
A40: S0024262981742 | B40: S0024683376530 | C40: =COUNTIF(A:A,B40) -> 1
A41: S0024749832812 | B41: S0024683376545 | C41: =COUNTIF(A:A,B41) -> 2
A42: S0024782192318 | B42: S0024683376541 | C42: =COUNTIF(A:A,B42) -> 1
A43: S0024746975982 | B43: S0024234551777 | C43: =COUNTIF(A:A,B43) -> 2
...

Sheet 엑셀 일괄 입고요청 사용법 및 유의사항
A1: ✔ 엑셀 일괄 입고요청 안내 1. 입고할 수량 - 1~5,000사이의 정수로 입력해주세요. 유효하지 않은 수/미기입 시 입고요청 상품 리스트에서 자동 누락됩니다. 2. 유통기한(소비기한)/제조일자/생산년도 - 실물에 유통기한이 표기된 상품인 경우 반드시 정확한 일자를 입력해 주시기 바랍니다. 카테고리별 필수 기입 항목이 다를 수 있습니다. - 실물에 유통기한이 존재하나 입력불필요 처리되어있는 경우 입고하지 마시고 로켓그로스 담당자에게 연락해 주십시오. 아무런 조치없이 그대로 입고 시 회송됩니다. - 작성양식: 유통(소비)기한/제조일자: YYYY-MM-DD, 생산년도: YYYY (예: 유통기한/제조일자 2021-08-12, 생산년도 2021) 2. 업로드 위치 및 주의사항 - 필수 입력사항을 모두 입력하여, [입고 요청하기] 페이지의 [엑셀업로드] 영역에서 파일을 업로드해 주세요. - 동일상품 중복 입력 시: 우선 입력된 상품(옵션)의 정보로 자동 적용됩니다. (예: 1번,7번에 같은 옵션 ID에 대한 정보가 있을 경우, 1번에 입력된 정보로 반영) - 엑셀 재업로드 시: 기존의 데이터는 삭제되고, 최종 업로드된 엑셀의 상품 리스트로 자동 적용됩니다. - 옵션은 최대 200개까지 업로드 가능합니다. 200개 이상 입력된 파일 업로드 시 오류가 발생합니다. - 이미 입고한 상품의 경우 정보를 변경하여도 반영되지 않습니다.
A3: ✔유의사항 - 본 자료는 판매자님의 이해를 돕기 위하여 참고용으로 마련되었습니다. - 본 자료에 포함된 정보는 당사의 영업비밀에 해당하므로, 제공된 목적 외로 제3자에게 공유하거나 유출하지 않도록 각별히 주의하시기 바랍니다. - 또한, 실제로 판매되는 수량, 매출액 등을 보장하지 않으며, 서비스 이용료 및 비용은 판매자님이 입력하는 입고수량을 기준으로 계산한 것이므로 실제로 부과되는 비용과 다를 수 있습니다. - 본 자료는 판매자님이 엑셀을 다운로드하는 시점에 Wing에 등록된 판매 정보(가격 등)가 반영되어 있습니다. Wing에 등록된 판매 정보의 변경 및 엑셀을 다운로드하는 시점에 따라 본 자료의 정보도 달라질 수 있습니다. - 엑셀 내에서는 가격을 포함한 상품의 판매 정보 수정이 불가합니다. 수정이 필요한 경우에는 WING [상품 조회/수정 페이지] 및 가격 수정 페이지에서 직접 수정하여 주시기 바랍니다. - 판매자배송 상품으로 바로 엑셀 일괄 입고요청을 한 경우, 엑셀을 업로드 하고 난 뒤 [다음]을 누르면 판매자배송 등록상품 ID 하위에 로켓그로스 옵션ID가 생성됩니다. [상품 조회 및 수정] 페이지에서 확인해주세요. - 판매자배송 상품을 처음 입고요청한 경우, 재고를 쿠팡풀필먼트센터에 입고가 완료되기 전까지 판매가 이루어지지 않습니다. 입고요청 후에 반드시 재고를 쿠팡풀필먼트센터로 보내주세요. - 바코드, 유통기간, 상품 크기와 중량 등의 물류정보를 변경하고 싶으신 경우, WING [상품 조회 및 수정]에서 등록상품ID를 검색하여 수정하여 주시기 바랍니다. 쿠팡풀필먼트센터에 도착 한 뒤에는 수정이 불가하니, 참고해주시기 바랍니다.
